Traceback (most recent call last):
  File "/opt/homebrew/Caskroom/miniconda/base/envs/pycbc_test/lib/python3.9/site-packages/nbclient/client.py", line 778, in _async_poll_for_reply
    msg = await ensure_async(self.kc.shell_channel.get_msg(timeout=new_timeout))
  File "/opt/homebrew/Caskroom/miniconda/base/envs/pycbc_test/lib/python3.9/site-packages/jupyter_core/utils/__init__.py", line 182, in ensure_async
    result = await obj
  File "/opt/homebrew/Caskroom/miniconda/base/envs/pycbc_test/lib/python3.9/site-packages/jupyter_client/channels.py", line 315, in get_msg
    raise Empty
_queue.Empty

During handling of the above exception, another exception occurred:

Traceback (most recent call last):
  File "/opt/homebrew/Caskroom/miniconda/base/envs/pycbc_test/lib/python3.9/site-packages/jupyter_cache/executors/utils.py", line 51, in single_nb_execution
    executenb(
  File "/opt/homebrew/Caskroom/miniconda/base/envs/pycbc_test/lib/python3.9/site-packages/nbclient/client.py", line 1305, in execute
    return NotebookClient(nb=nb, resources=resources, km=km, **kwargs).execute()
  File "/opt/homebrew/Caskroom/miniconda/base/envs/pycbc_test/lib/python3.9/site-packages/jupyter_core/utils/__init__.py", line 166, in wrapped
    return loop.run_until_complete(inner)
  File "/opt/homebrew/Caskroom/miniconda/base/envs/pycbc_test/lib/python3.9/asyncio/base_events.py", line 642, in run_until_complete
    return future.result()
  File "/opt/homebrew/Caskroom/miniconda/base/envs/pycbc_test/lib/python3.9/site-packages/nbclient/client.py", line 705, in async_execute
    await self.async_execute_cell(
  File "/opt/homebrew/Caskroom/miniconda/base/envs/pycbc_test/lib/python3.9/site-packages/nbclient/client.py", line 1001, in async_execute_cell
    exec_reply = await self.task_poll_for_reply
  File "/opt/homebrew/Caskroom/miniconda/base/envs/pycbc_test/lib/python3.9/site-packages/nbclient/client.py", line 802, in _async_poll_for_reply
    error_on_timeout_execute_reply = await self._async_handle_timeout(timeout, cell)
  File "/opt/homebrew/Caskroom/miniconda/base/envs/pycbc_test/lib/python3.9/site-packages/nbclient/client.py", line 852, in _async_handle_timeout
    raise CellTimeoutError.error_from_timeout_and_cell(
nbclient.exceptions.CellTimeoutError: A cell timed out while it was being executed, after 30 seconds.
The message was: Cell execution timed out.
Here is a preview of the cell contents:
-------------------
['def cooling_hot_water(drinking_temp):', '    boiling_temp = 100 # boiling water temp. 100 degrees', '    current_temp = boiling_temp # current temp of the drink', '    ice_cube_temp  = -5 # adding one ice cube drops the temp by 5 degrees', '    number_of_ice_cubes = 0 # number of ice-cubes that has been added so far']
...
['        print(f"The current temperature of your drink is {current_temp}, number of ice cubes added to the drink is {number_of_ice_cubes}")', '    return current_temp', '', 'drinking_temp = 35', 'cooling_hot_water(drinking_temp)']
-------------------

